{
 "cells": [
  {
   "cell_type": "code",
   "execution_count": 83,
   "metadata": {},
   "outputs": [],
   "source": [
    "import pandas as pd\n",
    "from pandas import DataFrame\n",
    "from pandas import concat\n",
    "from keras.models import load_model\n",
    "from sklearn.preprocessing import MinMaxScaler\n",
    "import numpy as np\n",
    "import joblib"
   ]
  },
  {
   "cell_type": "code",
   "execution_count": 84,
   "metadata": {},
   "outputs": [],
   "source": [
    "# Load and preprocess the data\n",
    "data = pd.read_csv(\"./../data_with_lagged.csv\", index_col=0) "
   ]
  },
  {
   "cell_type": "code",
   "execution_count": 85,
   "metadata": {},
   "outputs": [],
   "source": [
    "# Load the scaler and transform your data\n",
    "scaler = joblib.load('./../scaler.pkl')\n",
    "data_scaled = scaler.transform(data)"
   ]
  },
  {
   "cell_type": "code",
   "execution_count": 86,
   "metadata": {},
   "outputs": [
    {
     "ename": "ValueError",
     "evalue": "in user code:\n\n    File \"c:\\Users\\igor\\Desktop\\fyp\\fyp-env\\lib\\site-packages\\keras\\src\\engine\\training.py\", line 2440, in predict_function  *\n        return step_function(self, iterator)\n    File \"c:\\Users\\igor\\Desktop\\fyp\\fyp-env\\lib\\site-packages\\keras\\src\\engine\\training.py\", line 2425, in step_function  **\n        outputs = model.distribute_strategy.run(run_step, args=(data,))\n    File \"c:\\Users\\igor\\Desktop\\fyp\\fyp-env\\lib\\site-packages\\keras\\src\\engine\\training.py\", line 2413, in run_step  **\n        outputs = model.predict_step(data)\n    File \"c:\\Users\\igor\\Desktop\\fyp\\fyp-env\\lib\\site-packages\\keras\\src\\engine\\training.py\", line 2381, in predict_step\n        return self(x, training=False)\n    File \"c:\\Users\\igor\\Desktop\\fyp\\fyp-env\\lib\\site-packages\\keras\\src\\utils\\traceback_utils.py\", line 70, in error_handler\n        raise e.with_traceback(filtered_tb) from None\n    File \"c:\\Users\\igor\\Desktop\\fyp\\fyp-env\\lib\\site-packages\\keras\\src\\engine\\input_spec.py\", line 235, in assert_input_compatibility\n        raise ValueError(\n\n    ValueError: Exception encountered when calling layer 'sequential_7' (type Sequential).\n    \n    Input 0 of layer \"bidirectional_14\" is incompatible with the layer: expected ndim=3, found ndim=2. Full shape received: (None, 1)\n    \n    Call arguments received by layer 'sequential_7' (type Sequential):\n      • inputs=tf.Tensor(shape=(None, 1), dtype=int64)\n      • training=False\n      • mask=None\n",
     "output_type": "error",
     "traceback": [
      "\u001b[1;31m---------------------------------------------------------------------------\u001b[0m",
      "\u001b[1;31mValueError\u001b[0m                                Traceback (most recent call last)",
      "Cell \u001b[1;32mIn[86], line 14\u001b[0m\n\u001b[0;32m     11\u001b[0m model \u001b[38;5;241m=\u001b[39m load_model(\u001b[38;5;124m'\u001b[39m\u001b[38;5;124m./bilstm_model.h5\u001b[39m\u001b[38;5;124m'\u001b[39m)  \u001b[38;5;66;03m# Update with the actual path to your model\u001b[39;00m\n\u001b[0;32m     13\u001b[0m \u001b[38;5;66;03m# Make predictions\u001b[39;00m\n\u001b[1;32m---> 14\u001b[0m predictions \u001b[38;5;241m=\u001b[39m \u001b[43mmodel\u001b[49m\u001b[38;5;241;43m.\u001b[39;49m\u001b[43mpredict\u001b[49m\u001b[43m(\u001b[49m\u001b[43mdata_reshaped\u001b[49m\u001b[43m)\u001b[49m\n",
      "File \u001b[1;32mc:\\Users\\igor\\Desktop\\fyp\\fyp-env\\lib\\site-packages\\keras\\src\\utils\\traceback_utils.py:70\u001b[0m, in \u001b[0;36mfilter_traceback.<locals>.error_handler\u001b[1;34m(*args, **kwargs)\u001b[0m\n\u001b[0;32m     67\u001b[0m     filtered_tb \u001b[38;5;241m=\u001b[39m _process_traceback_frames(e\u001b[38;5;241m.\u001b[39m__traceback__)\n\u001b[0;32m     68\u001b[0m     \u001b[38;5;66;03m# To get the full stack trace, call:\u001b[39;00m\n\u001b[0;32m     69\u001b[0m     \u001b[38;5;66;03m# `tf.debugging.disable_traceback_filtering()`\u001b[39;00m\n\u001b[1;32m---> 70\u001b[0m     \u001b[38;5;28;01mraise\u001b[39;00m e\u001b[38;5;241m.\u001b[39mwith_traceback(filtered_tb) \u001b[38;5;28;01mfrom\u001b[39;00m \u001b[38;5;28;01mNone\u001b[39;00m\n\u001b[0;32m     71\u001b[0m \u001b[38;5;28;01mfinally\u001b[39;00m:\n\u001b[0;32m     72\u001b[0m     \u001b[38;5;28;01mdel\u001b[39;00m filtered_tb\n",
      "File \u001b[1;32m~\\AppData\\Local\\Temp\\__autograph_generated_filen10b9ml8.py:15\u001b[0m, in \u001b[0;36mouter_factory.<locals>.inner_factory.<locals>.tf__predict_function\u001b[1;34m(iterator)\u001b[0m\n\u001b[0;32m     13\u001b[0m \u001b[38;5;28;01mtry\u001b[39;00m:\n\u001b[0;32m     14\u001b[0m     do_return \u001b[38;5;241m=\u001b[39m \u001b[38;5;28;01mTrue\u001b[39;00m\n\u001b[1;32m---> 15\u001b[0m     retval_ \u001b[38;5;241m=\u001b[39m ag__\u001b[38;5;241m.\u001b[39mconverted_call(ag__\u001b[38;5;241m.\u001b[39mld(step_function), (ag__\u001b[38;5;241m.\u001b[39mld(\u001b[38;5;28mself\u001b[39m), ag__\u001b[38;5;241m.\u001b[39mld(iterator)), \u001b[38;5;28;01mNone\u001b[39;00m, fscope)\n\u001b[0;32m     16\u001b[0m \u001b[38;5;28;01mexcept\u001b[39;00m:\n\u001b[0;32m     17\u001b[0m     do_return \u001b[38;5;241m=\u001b[39m \u001b[38;5;28;01mFalse\u001b[39;00m\n",
      "\u001b[1;31mValueError\u001b[0m: in user code:\n\n    File \"c:\\Users\\igor\\Desktop\\fyp\\fyp-env\\lib\\site-packages\\keras\\src\\engine\\training.py\", line 2440, in predict_function  *\n        return step_function(self, iterator)\n    File \"c:\\Users\\igor\\Desktop\\fyp\\fyp-env\\lib\\site-packages\\keras\\src\\engine\\training.py\", line 2425, in step_function  **\n        outputs = model.distribute_strategy.run(run_step, args=(data,))\n    File \"c:\\Users\\igor\\Desktop\\fyp\\fyp-env\\lib\\site-packages\\keras\\src\\engine\\training.py\", line 2413, in run_step  **\n        outputs = model.predict_step(data)\n    File \"c:\\Users\\igor\\Desktop\\fyp\\fyp-env\\lib\\site-packages\\keras\\src\\engine\\training.py\", line 2381, in predict_step\n        return self(x, training=False)\n    File \"c:\\Users\\igor\\Desktop\\fyp\\fyp-env\\lib\\site-packages\\keras\\src\\utils\\traceback_utils.py\", line 70, in error_handler\n        raise e.with_traceback(filtered_tb) from None\n    File \"c:\\Users\\igor\\Desktop\\fyp\\fyp-env\\lib\\site-packages\\keras\\src\\engine\\input_spec.py\", line 235, in assert_input_compatibility\n        raise ValueError(\n\n    ValueError: Exception encountered when calling layer 'sequential_7' (type Sequential).\n    \n    Input 0 of layer \"bidirectional_14\" is incompatible with the layer: expected ndim=3, found ndim=2. Full shape received: (None, 1)\n    \n    Call arguments received by layer 'sequential_7' (type Sequential):\n      • inputs=tf.Tensor(shape=(None, 1), dtype=int64)\n      • training=False\n      • mask=None\n"
     ]
    }
   ],
   "source": [
    "train_ratio = 0.85\n",
    "data_len = len(data)\n",
    "train_size = int(data_len*train_ratio)\n",
    "train = data.iloc[:train_size]\n",
    "test = data.iloc[train_size:]\n",
    "test_y = test[\"var1(t)\"].values\n",
    "\n",
    "data_reshaped = test_y.reshape(len(test_y), 1)\n",
    "\n",
    "# Load your BiLSTM model\n",
    "model = load_model('./../bilstm_model.h5')  # Update with the actual path to your model\n",
    "\n",
    "# Make predictions\n",
    "predictions = model.predict(data_reshaped)"
   ]
  },
  {
   "cell_type": "code",
   "execution_count": null,
   "metadata": {},
   "outputs": [],
   "source": [
    "# Predict using the model\n",
    "predictions = model.predict(data_reshaped)\n",
    "\n",
    "# Post-process the predictions as needed to interpret the results"
   ]
  }
 ],
 "metadata": {
  "kernelspec": {
   "display_name": "fyp-env",
   "language": "python",
   "name": "python3"
  },
  "language_info": {
   "codemirror_mode": {
    "name": "ipython",
    "version": 3
   },
   "file_extension": ".py",
   "mimetype": "text/x-python",
   "name": "python",
   "nbconvert_exporter": "python",
   "pygments_lexer": "ipython3",
   "version": "3.10.11"
  }
 },
 "nbformat": 4,
 "nbformat_minor": 2
}
